Workbook

Sheet GENERAL
A1: CONDICIÓN | B1: CODIGO PRESTACION | C1: NOMBRE PRESTACIÓN | D1: TIPO PRESTACION | E1: LUGAR DE ATENCIÓN | F1: PERSONAL QUE ATIENDE | G1: RANGO DE EDAD | H1: DESTINO DE ASEGURADO | I1: SERVICIOS PREVENTIVOS | J1: DATO | K1: TOPES | L1: DIAGNOSTICOS A REGISTRAR | M1: PROCEDIMIENTOS OBLIGATORIOS | N1: MEDICAMENTO E INSUMOS
A2: ADOLESCENTE | B2: COD_017 | C2: =VLOOKUP(B2,SER!A:C,2,FALSE) -> Atención Integral del adolescente | D2: =VLOOKUP(B2,SER!A:C,3,FALSE) -> Preventivo | E2: * Intramural ° Extramural | F2: * I-1 : Tec. Enfermeria, Lic. Enfermeria, Obstetra, Medico * I-2 : Tec. Enfermeria, Lic. Enfermeria, Obstetra, Medico * I-3 :Lic. Enfermeria (e), Obstetra, Medico, psicologo * I-4 : Obstetra, Medico, ME, psicologo | G2: * Edad minima: 12 años * Edad Maxima: 17 años SEXO: * Ambos | H2: * Alta: en sesion 3 * Citado: solo en sesion 1 y 2 | I2: OBLIGATORIO: * 005 - Edad Gestacional * 003 - Peso * 004 - Talla * 014 - IMC * 015 - PAB * 301 - P.A(mmHg) OPCIONAL: 407 - Tamizaje de salud mental | K2: * Dia: 01 * Mes: 01 * Año: 03 | L2: OBLIGATORIO: * Z003 - Exámen del estado de desarrollo del Adolescente (Adolescente normal) OPCIONALES : * E43X - Desnutrición Proteico calórica Severa, No Especificada (Delgadez severa) * Z91.8 - Historia personal de otros factores de riesgo, no clasificados en otra parte (Riesgo de desnutrición). * E440 - Desnutrición Proteico calórica Moderada (Delgadez) * E660 - Obesidad debida a exceso de Calorías (Sobrepeso) * E669 - Obesidad, No especificada ADICIONAL: * E45X - Retardo del Desarrollo debido a Desnutrición Proteico calórica (Talla baja) * E344 - Estatura alta Constitucional (Talla alta) | M2: OBLIGATORIO: *99384 - ATENCIÓN INTEGRAL DE SALUD DEL ADOLESCENTE DE 12 A 17 AÑOS OPCIONAL: * 85018 - Dosaje de Hemoglobina Ó * 85007 - Hemograma Ó * 85027 - Hemograma Completo Ó * 85031 - Hemograma completo, tercera generación
A3: GESTANTE | B3: COD_009 | C3: =VLOOKUP(B3,SER!A:C,2,FALSE) -> Atención prenatal | D3: =VLOOKUP(B3,SER!A:C,3,FALSE) -> Preventivo | E3: * Intramural | F3: * I-1 : Tec. Enfermeria, Lic. Enfermeria, Obstetra, Medico * I-2 : Tec. Enfermeria, Lic. Enfermeria, Obstetra, Medico * I-3 : Obstetra, Medico * I-4 : Obstetra, Medico, ME | G3: * Edad minima: 09 Años * Edad Maxima: 60 Años SEXO: * Femenino | H3: * Citado | I3: OBLIGATORIO: * 003 - Peso * 004 - Talla * 010 - Altura uterina * 301 - P.A(mmHg) * 300 - CPN * 005 - Edad Gestacional embarazo (en Semanas) OPCIONAL: * 014 - IMC * 015 - PAB | K3: * Dia: 01 * Mes: 04 * Año: 13 DESDE LA PRIMERA ATENCIÓN DE GESTANTE | L3: OPCIONALES: * Z340 - SUPERVISION DE PRIMER EMBARAZO NORMAL * Z348 - SUPERVISION DE OTROS EMBARAZOS NORMALES * Z349 - SUPERVISION DE EMBARAZO NORMAL NO ESPECIFICADO * Z350 - SUPERVISION DE EMBARAZO CON HISTORIA DE ESTERILIDAD * Z351 - SUPERVISION DE EMBARAZO CON HISTORIA DE ABORTO * Z352 - SUPERVISION DE EMBARAZO CON OTRO RIESGO EN LA HISTORIA OBSTETRICA O REPRODUCTIVA * Z353 - SUPERVISION DE EMBARAZO CON HISTORIA DE INSUFICIENTE ATENCION PRENATAL * Z354 - SUPERVISION DE EMBARAZO CON GRAN MULTIPARIDAD * Z355 - SUPERVISION DE PRIMIGESTA AÑOSA * Z356 - SUPERVISION DE PRIMIGESTA MUY JOVEN * Z358 - SUPERVISION DE OTROS EMBARAZOS DE ALTO RIESGO * Z359 - SUPERVISION DE EMBARAZO DE ALTO RIESGO, SIN OTRA ESPECIFICACION | M3: OBLIGATORIO: * 59401 - Atención Prenatal * 99402.01 - Consejeria en signos de alarma (embarazo, puerperio) OPCIONAL: * 85018 - Dosaje de Hemoglobina Ó | N3: * 00200 - Acido folico (hasta las 13ss) * 03513 - Ácido Fólico + Ferroso Sulfato (Equiv. De Hierro elemental) (apartir de 14 ss hasta culminar el embarazo) 33577 HIERRO ELEMENTAL 35542 3552 20635 * 020635 - Carbonato de Calcio (apartir de de las 20ss)
A4: JOVEN | B4: COD_904 | C4: =VLOOKUP(B4,SER!A:C,2,FALSE) -> Atención Integral de Salud del Joven y Adulto | D4: =VLOOKUP(B4,SER!A:C,3,FALSE) -> Preventivo | E4: * Intramural ° Extramural | F4: * I-1 : Tec. Enfermeria, Lic. Enfermeria, Obstetra, Medico * I-2 : Lic. Enfermeria, Obstetra, Medico * I-3 :Lic. Enfermeria, Obstetra, Medico. * I-4 : Lic. Enfermeria, Obstetra, Medico, ME. | G4: * Edad minima: 18 años * Edad Maxima: 59 años SEXO: * Ambos | H4: * Alta * Citado | I4: CONDICIONAL: * 005 - Edad Gestacional embarazo (en Semanas) OBLIGATORIO: * 003 - Peso * 004 - Talla * 014 - IMC * 015 - PAB * 301 - P.A(mmHg) * 401 - Evaluación Integral de Salud del joven o adulto anual (Eval. Joven y Adulto) | J4: Ap. Dx/Proc | K4: * Dia: 01 * Mes: 02 * Año: 04 | L4: OBLIGATORIO: * Z000 - EXAMEN MEDICO GENERAL(NORMAL) Z008 OTROS EXAMENES GENERALES (NORMAL) OPCIONALES: * E440 - Desnutrición Proteico calórica Moderada (Delgadez) ó * E660 - Obesidad debida a exceso de Calorías (Sobrepeso) ó * E669 - Obesidad, No especificada . | M4: RC31: * 85018 - Dosaje de Hemoglobina OPCIONAL: * 82947 - Glucosa Basal (Colocar Resultado Númerico) * 82465 - Colesterol Total (Colocar Resultado (Normal ó Patologico * 84478 - Trigliceridos ( Colocar Resultado Valor OJO TAMBEIN PUEDE IR ANEXADO CON LA PRESTACON 071 EXAMENES DE LABORATORIO
A5: MATERNO | B5: COD_119 | C5: =VLOOKUP(B5,SER!A:C,2,FALSE) -> Control de crecimiento y desarrollo en menores de 10 - 12 años | D5: =VLOOKUP(B5,SER!A:C,3,FALSE) -> Preventivo | E5: * Intramural | F5: * I-1 : Tec. Enfermeria, Lic. Enfermeria, Obstetra, Medico * I-2 : Tec. Enfermeria , Lic. Enfermeria, Obstetra, Medico * I-3 :Lic. Enfermeria, Nutricionista, Medico. * I-4 : Lic. Enfermeria, Nutricionista, Medico, ME. | G5: ETAPA DE VIDA: * 10 A 11 Años RANGO DE EDAD: * Edad minima: 10 Años * Edad Maxima: 11 Años SEXO: * Ambos | H5: * Alta SIEMPRE ES ALTA YA QUE SOLO LE CORRESPONDE UN SOLO CRED | I5: OBLIGATORIO: * 003 - Peso * 004 - Talla * 019 - Prematuro al Nacer * 020 - Bajo peso al nacer * 021 - Enfermedades Congénita/Secuelas de Nacimiento * 120 - Control CRED | K5: * Dia: 01 * Mes: 01 * Año: 01 | L5: OBLIGATORIO: *Z001 - Control de Salud de rutina del niño (Niño Normal) OPCIONALES: * E43X - Desnutrición Proteico calórica Severa, No Especificada (Delgadez severa) Ó * Z91.8 - Historia personal de otros factores de riesgo, no clasificados en otra parte (Riesgo de desnutrición). Ó * E440 - Desnutrición Proteico calórica Moderada (Delgadez) Ó * E660 - Obesidad debida a exceso de Calorías (Sobrepeso) Ó * E669 - Obesidad, No especificada ADICIONAL: * E45X - Retardo del Desarrollo debido a Desnutrición Proteico calórica (Talla baja) Ó * E344 - Estatura alta Constitucional (Talla alta) | M5: OPCIONAL: * 99383 - Control de Crecimiento y Desarrollo de niños de 5 a 11 años * 85018 - Dosaje de Hemoglobina Ó * 85007 - Hemograma Ó * 85027 - Hemograma Completo Ó * 85031 - Hemograma completo, tercera generación
A6: NEONATO | B6: COD_001 | C6: =VLOOKUP(B6,SER!A:C,2,FALSE) -> Control de crecimiento y desarrollo en menores de 0 - 4 años | D6: =VLOOKUP(B6,SER!A:C,3,FALSE) -> Preventivo | E6: * Intramural | F6: * I-1 : Lic. Enfermeria, Obstetra, Personal Capacitado * I-2 : Medico, Lic. Enfermeria, Obstetra, Personal Capacitado * I-3 : Lic. Enfermeria, Nutricionista, Medico * I-4 : Lic. Enfemeria, Nutricionista, Medico, ME | G6: RANGO DE EDAD: * Edad minima: 00 dias * Edad Maxima: 4 años SEXO: * Ambos | H6: * Alta * Citado | I6: OBLIGATORIO: * 003 - Peso * 004 - Talla * 019 - Prematuro al Nacer * 020 - Bajo peso al nacer * 021 - Enfermedades Congénita/Secuelas de Nacimiento * 120 - Control CRED | K6: * 04 CRED Entre 0 - 28 dias | L6: OBLIGATORIO: * Z001 - Control de Salud de rutina del niño (Niño Normal) OPCIONAL SEGÚN CORRESPONDA A LOS SERVICOS PREVENTIVOS : * E45X - Desnutrición Proteico calórica Severa, No Especificada (Delgadez severa) Ó * E440 - Desnutrición Proteico calórica Moderada (Delgadez) * Z918 - historia personal. | M6: Obligatorios: * 99381 - ATENCIÓN INTEGRAL DE SALUD DEL NIÑO CRED <1 año. * 99382 - ATENCIÓN INTEGRAL DE SALUD DEL NIÑO CRED 1 año.a 4 años ADICIONAL * 90471 - Inmunización segun a sus vacunas y/o edad. * 99401.07 - Consejeria en Inmunizaciónes * 85018 /85007 /85057 / 85031 - DOSAJE DE HEMOGLOBINA (VALOR AJUSTADO) (SI EL VALOR DE HEMOGLOBINA ESTA POR DEBAJO DE LOS RANGOS NORMALES DEBERA SER REGISTRADO EL DIAGNOSTICO DE ANEMIA) | N6: 8153 - Retinol Tab- 200 mg
A7: Neonato | B7: COD_002 | C7: =VLOOKUP(B7,SER!A:C,2,FALSE) -> Control del recién nacido con menos de 2,500 gr, prematuro, con secuelas al nacer | D7: =VLOOKUP(B7,SER!A:C,3,FALSE) -> Preventivo | E7: * Intramural | F7: * I-1 : Tec. Enfermeria, Lic. Enfermeria * I-2 : Lic. Enfermeria * I-3 : Lic. Enfermeria, Medico * I-4 : Lic. Enfemeria, Medico, ME | G7: RANGO DE EDAD: * Edad minima: 00 dias * Edad Maxima: 12 meses SEXO: * Ambos | H7: * Alta * Citado | I7: OBLIGATORIO: * 003 - Peso * 004 - Talla * 019 - Prematuro al Nacer * 020 - Bajo peso al nacer * 021 - Enfermedades Congénita/Secuelas de Nacimiento * 120 - Control CRED OPCIONAL: * 014 - IMC * 015 - PAB | K7: * Dia: 01 * Mes: 05 * Año: 18 NACIMIENTO | L7: OBLIGATORIO : * Z91.8 - Historia personal de otros factores de riesgo, no clasificados en otra parte (Riesgo de desnutrición). Ó * E43X - Desnutrición Proteico calórica Severa, No Especificada (Delgadez severa) Ó * E440 - Desnutrición Proteico calórica Moderada (Delgadez) Ó * E660 - Obesidad debida a exceso de Calorías (Sobrepeso) Ó * E669 - Obesidad, No especificada ADICIONAL : * E45X - Retardo del Desarrollo debido a Desnutrición Proteico calórica (Talla baja) Ó * E344 - Estatura alta Constitucional (Talla alta) | M7: OBLIGATORIO * 99381 - ATENCIÓN INTEGRAL DE SALUD DEL NIÑO CRED <1 año. ADICIONAL: * 99252 - CONSEJERIA NUTRICIONAL EN NIÑOS EN RIESGOS * 90471 - Inmunización * 36416 - COLECCIÓN DE SANGRE CAPILAR (ejemplo dedo,talon u oreja) (a partir de I-4) * 85018 /85007 /85057 / 85031 - DOSAJE DE HEMOGLOBINA (VALOR AJUSTADO) (SI EL VALOR DE HEMOGLOBINA ESTA POR DEBAJO DE LOS RANGOS NORMALES DEBERA SER REGISTRADO EL DIAGNOSTICO DE ANEMIA)
A8: NIÑO | B8: COD_001 | C8: =VLOOKUP(B8,SER!A:C,2,FALSE) -> Control de crecimiento y desarrollo en menores de 0 - 4 años | D8: =VLOOKUP(B8,SER!A:C,3,FALSE) -> Preventivo | E8: * Intramural | F8: * I-1 : Lic. Enfermeria, Obstetra, Personal Capacitado * I-2 : Medico, Lic. Enfermeria, Obstetra, Personal Capacitado * I-3 : Lic. Enfermeria, Nutricionista, Medico * I-4 : Lic. Enfemeria, Nutricionista, Medico, ME | G8: RANGO DE EDAD: * Edad minima: 00 dias * Edad Maxima: 4 años SEXO: * Ambos | H8: * Alta * Citado | I8: OBLIGATORIO: * 003 - Peso * 004 - Talla * 307 - Consejeria Nutricional * 019 - Prematuro al Nacer * 020 - Bajo peso al nacer * 021 - Enfermedades Congénita/Secuelas de Nacimiento * 120 - Control CRED OPCIONAL: * 407 - Tamizaje de salud mental | L8: OBLIGATORIO: * Z001 - Control de Salud de rutina del niño (Niño Normal) OPCIONAL: * E43X - Desnutrición Proteico calórica Severa, No Especificada (Delgadez severa) Ó * Z91.8 - Historia personal de otros factores de riesgo, no clasificados en otra parte (Riesgo de desnutrición). Ó * E440 - Desnutrición Proteico calórica Moderada (Delgadez) ) Ó * E660 - Obesidad debida a exceso de Calorías (Sobrepeso) Ó * E669 - Obesidad, No especificada ADICIONAL : * E45X - Retardo del Desarrollo debido a Desnutrición Proteico calórica (Talla baja) Ó * E344 - Estatura alta Constitucional (Talla alta) | M8: OPCIONALES: * 99381 - ATENCIÓN INTEGRAL DE SALUD DEL NIÑO CRED <1 año. * 99382 - ATENCIÓN INTEGRAL DE SALUD DEL NIÑO CRED 1 año.a 4 años * 99403 - CONSEJERIA NUTRICIONAL ( DX Grupo A) ADICIONAL * 90471 - Inmunización * 36416 - COLECCIÓN DE SANGRE CAPILAR (ejemplo dedo,talon u oreja) (a partir de I-4) * 85018- DOSAJE DE HEMOGLOBINA (VALOR AJUSTADO) (SI EL VALOR DE HEMOGLOBINA ESTA POR DEBAJO DE LOS RANGOS NORMALES DEBERA SER REGISTRADO EL DIAGNOSTICO DE ANEMIA) | N8: 8153 - Retinol Tab- 200 mg
A9: NIÑO | B9: COD_002 | C9: =VLOOKUP(B9,SER!A:C,2,FALSE) -> Control del recién nacido con menos de 2,500 gr, prematuro, con secuelas al nacer | D9: =VLOOKUP(B9,SER!A:C,3,FALSE) -> Preventivo | E9: * Intramural * Extramural (opcional) | F9: * I-1 : Tec. Enfermeria,, Lic. Enfermeria * I-2 : Lic. Enfermeria * I-3 : Lic. Enfermeria, Medico * I-4 : Lic. Enfemeria, Medico, ME | G9: RANGO DE EDAD: * Edad minima: 00 dias * Edad Maxima: 12 meses SEXO: * Ambos | H9: * Alta * Citado | I9: OBLIGATORIO: * 003 - Peso * 004 - Talla * 307 - Consejeria Nutricional * 019 - Prematuro al Nacer * 020 - Bajo peso al nacer * 021 - Enfermedades Congénita/Secuelas de Nacimiento * 120 - Control CRED * 002 - Lactancia Materna Exclusiva OPCIONAL: 407 - Tamizaje de salud mental | K9: * Dia: 01 * Mes: 05 * Año: NACIMIENTO | L9: OBLIGATORIO : * Z91.8 - Historia personal de otros factores de riesgo, no clasificados en otra parte (Riesgo de desnutrición). Ó * E43X - Desnutrición Proteico calórica Severa, No Especificada (Delgadez severa) Ó * E440 - Desnutrición Proteico calórica Moderada (Delgadez) Ó * E660 - Obesidad debida a exceso de Calorías (Sobrepeso) Ó * E669 - Obesidad, No especificada ADICIONAL : * E45X - Retardo del Desarrollo debido a Desnutrición Proteico calórica (Talla baja) Ó * E344 - Estatura alta Constitucional (Talla alta) | M9: OBLIGATORIO * 99381 - ATENCIÓN INTEGRAL DE SALUD DEL NIÑO CRED <1 año. ADICIONAL: * 90471 - Inmunización * 85018 /85007 /85057 / 85031 - DOSAJE DE HEMOGLOBINA (VALOR AJUSTADO) (SI EL VALOR DE HEMOGLOBINA ESTA POR DEBAJO DE LOS RANGOS NORMALES DEBERA SER REGISTRADO EL DIAGNOSTICO DE ANEMIA)
A10: NIÑO | B10: COD_016 | C10: =VLOOKUP(B10,SER!A:C,2,FALSE) -> Estimulación temprana para menores de 36 meses | D10: =VLOOKUP(B10,SER!A:C,3,FALSE) -> Preventivo | E10: * Intramural | F10: * I-1 : Tec. Enfermeria, Lic. Enfermeria, Obstetra, Medico * I-2 : Tec. Enfermeria , Lic. Enfermeria, Obstetra, Medico * I-3 :Lic. Enfermeria, Medico. * I-4 : Lic. Enfermeria, Medico, ME. | G10: RANGO DE EDAD: * Edad minima: 00 dias * Edad Maxima: 35 meses Y 29 Dias SEXO: * Ambos | H10: * Alta * Citado | I10: OBLIGATORIO: RC05: * 003 - Peso * 004 - Talla | K10: * Dia: 01 * Mes: 01 * Año: 12 | L10: OBLIGATORIO: * Z001 - Control de Salud de rutina del niño (Niño Normal) | M10: OBLIGATORIO * 99401.05 - Consejeria en atencion y estimulacion temprana del desarrollo.
A11: NIÑO | B11: COD_007 | C11: =VLOOKUP(B11,SER!A:C,2,FALSE) -> Suplemento de micronutrientes | D11: =VLOOKUP(B11,SER!A:C,3,FALSE) -> Preventivo | E11: * Intramural * Extramural | F11: * I-1 : Tec. Enfermeria, Lic. Enfermeria, Obstetra, Medico * I-2 : Tec. Enfermeria , Lic. Enfermeria, Obstetra, Medico * I-3 :Lic. Enfermeria, Nutricionista, Medico. * I-4 : Lic. Enfermeria, Nutricionista, Medico, ME. | G11: * Edad minima: 00 dias * Edad Maxima: 11 años SEXO: * Ambos | H11: * Alta * Citado | I11: OBLIGATORIO: RC14: * 003 - Peso * 004 - Talla | J11: * Med/Ins | K11: * Dia: 01 * Mes: 01 * Año: 12 * Intervalo: Ninguno EDAD CUMPLIDA | L11: * Z298 - Otras medidas profilacticas EN CASOS DE SER DIAGNOSTICADO CON ANEMIA: * D509 - ANEMIA REGISTRAR POR LO MENOS UNO DE LOS DOS DIAGNOSTICOS Z2981 ADMINISTRACION DE VITAMINA A Z2982 ADMINISTRACION DE SULFATO FERROSO | M11: OBLIGATORIO OPCIONAL: * 85018 - Dosaje de Hemoglobina Ó | N11: * S0001 - Sobre Chispita (Sulfato ferroso12.5 mg) ó *03519 - Sulfato ferroso frasco de 180 ml / 25 mg ó *03536 - Sulfato ferroso gotas de 30 ml / 25 mg ó * 01759 - Fierrro Polimaltosado 100 ml 50 mg/5 ml JBE ó * 03560 - Fierro Polimaltosado 30 ml 50 mg/ml SOL ó * 21643 - Fierro Polimaltosa 2 ml 50 mg/ml SOL ó * 28551 - Hierro Polimaltosado 20 ml 50 mg/ml SOL ó * 29165 - Complejo hidróxido de hierro Polimaltosa 30 ml 50 mg/ml SOL * 33524 - Fierro Polimaltosa 150 mL 50 mg/5 mL
A12: NIÑO | B12: COD_005 | C12: =VLOOKUP(B12,SER!A:C,2,FALSE) -> Consejería nutricional para niñas o niños en riesgo nutricional y desnutrición | D12: =VLOOKUP(B12,SER!A:C,3,FALSE) -> Preventivo | E12: * Intramural * Extramural | F12: * I-1 : Tec. Enfermeria, Lic. Enfermeria, Obstetra, Medico * I-2 : Tec. Enfermeria , Lic. Enfermeria, Obstetra, Medico * I-3 : Lic. Enfermeria, Nutricionista, Medico, ME. * I-4 : Lic. Enfermeria, Nutricionista, Medico, ME. | G12: * Edad minima: 00 dias * Edad Maxima: 11 años SEXO: * Ambos | H12: * Alta * Citado | I12: OBLIGATORIO: RC14: * 003 - Peso * 004 - Talla | K12: * Dia: 01 * Mes: 04 * Año: 12 * Intervalo: Ninguno EDAD CUMPLIDA | L12: OBLIGATORIO: * Z594 - Problemas relacionados con la falta de alimentos adecuados * E660 - 0besidad debida a exceso de calorias * E669 - Obesidad, no especificada OPCIONAL: * E45X - Retardo del desarrollo debido a desnutricion proteicocalorica ADICIONAL: * Z918 - Historia personal de otros factores de riesgo, no clasificados en otra parte * D538, D539, D649, D500, D508, D509: Anemia | M12: OBLIGATORIO * 99252 - Consejeria Nutricional en niños con riesgo OPCIONAL: * 85018 - Dosaje de Hemoglobina Ó
A13: GENERAL | B13: COD_008 | C13: =VLOOKUP(B13,SER!A:C,2,FALSE) -> Profilaxis antiparasitaria | D13: =VLOOKUP(B13,SER!A:C,3,FALSE) -> Preventivo | E13: * Intramural * Extramural | F13: * I-1 : Tec. Enfermeria, Lic. Enfermeria, Obstetra, Medico * I-2 : Tec. Enfermeria , Lic. Enfermeria, Obstetra, Medico * I-3 : Lic. Enfermeria, Nutricionista, Medico, ME. * I-4 : Lic. Enfermeria, Nutricionista, Medico, ME. | G13: * Edad minima: 02 años * Edad Maxima: 120 años SEXO: * Ambos | H13: * Alta * Citado | I13: OBLIGATORIO: * 003 - Peso * 004 - Talla | J13: * Med/Ins | K13: * Dia: 01 * Mes: 01 * Año: 02 * Intervalo: 06 meses EDAD CUMPLIDA | L13: OBLIGATORIO: * Z299 - MEDIDA PROFILACTICA no especificada | M13: OBLIGATORIO: * 99403.01 - Consejeria nutricional | N13: *00259 - Albendazol 100mg/5ml - menor a los 5 años *00269 - Albendazol 200mg - mayores de 5 años 4586 Mebendazol adultos
A14: JOVEN | B14: COD_019 | C14: =VLOOKUP(B14,SER!A:C,2,FALSE) -> Detección trastorno agudeza visual y ceguera | D14: =VLOOKUP(B14,SER!A:C,3,FALSE) -> Preventivo | E14: * Intramural | F14: * I-1 :Lic. Enfermeria, Obstetra, Medico * I-2 : Lic. Enfermeria, Obstetra, Medico * I-3 : Lic. Enfermeria, Obstetra, Medico, ME. * I-4 : Lic. Enfermeria,Obstetra, Medico, ME. | G14: * Edad minima: 00 dias * Edad Maxima: 120 años SEXO: * Ambos | H14: * Alta - SIEMPRE | I14: OBLIGATORIO: RC14: EN CASO DE GESTANTE * 005 - Edad Gestacional | J14: * Ap. Dx/Proc | K14: * Dia: 01 * Mes: 01 * Año: 01 * Intervalo: Ninguno EDAD CUMPLIDA | L14: OBLIGATORIO: * Z010 - EXAMEN DE OJOS Y DE LA VISIÓN | M14: OBLIGATORIO: * 92015 - Refracción y medición de la visión MENORES DE 5 AÑOS * 99173 - Determinación de Agudeza visual Bilatetral
A15: GENERAL | B15: COD_020 | C15: =VLOOKUP(B15,SER!A:C,2,FALSE) -> Salud Bucal | D15: =VLOOKUP(B15,SER!A:C,3,FALSE) -> Preventivo | E15: * Intramural * Extramural | F15: * I-1 : Odontologo * I-2 : Odontologo * I-3 : Odontologo * I-4 : Odontologo | G15: * Edad minima: 00 dias * Edad Maxima: 120 años SEXO: * Ambos | H15: * Alta * Citado | I15: OBLIGATORIO: * 005 - Edad Gestacional: EN CASO DE SER GESTANTE * 03 - PESO * 04 - TALLA | J15: * Ap. Dx/Proc | K15: * Dia: 01 * Mes: 01 * Año: 02 * Intervalo: Ninguna EDAD CUMPLIDA | L15: OBLIGATORIO: * Z768 - PERSONA EN CONTACTO CON LOS SERVICIOS DE SALUD EN OTRAS CIRCUNSTANCIAS ESPECIFICADAS | M15: OBLIGATORIO: * D0150 - Evaluación oral completa
A16: GENERAL | B16: COD_021 | C16: =VLOOKUP(B16,SER!A:C,2,FALSE) -> Prevencion de caries | D16: =VLOOKUP(B16,SER!A:C,3,FALSE) -> Preventivo | E16: * Intramural * Extramural | F16: * I-1 : Odontologo * I-2 : Odontologo * I-3 : Odontologo * I-4 : Odontologo | G16: * Edad minima: 06 meses * Edad Maxima: 120años SEXO: * Ambos | H16: * Alta * Citado | I16: RC14: * 005 - Edad Gestacional: EN CASO DE SER GESTANTE * 003 - PESO * 004 - TALLA | J16: * Ap. Dx/Proc | K16: * Dia: 01 * Mes: 04 * Año: 17 EDAD CUMPLIDA | L16: OBLIGATORIO: * Z298 - Otras medidas profilácticas | M16: OBLIGATORIO RC39: * D1110 - Profilaxis dental * D1206 - Aplicación flúor barniz - APLICACIÓN MENOR A LOS 12 AÑOS * D1204, D1208 - Aplicación tópica de flúor gel - APLICACIÓN MAYOR A LOS DE 12 AÑOS * D1351 - Aplicación de sellante por pieza dentaria *E1311 - Destartraje dental
A17: GENERAL | B17: COD_022 | C17: =VLOOKUP(B17,SER!A:C,2,FALSE) -> Detección de problemas en Salud Mental | D17: =VLOOKUP(B17,SER!A:C,3,FALSE) -> Preventivo | E17: * Intramural * Extramural | F17: * I-1 : Tec. Enfermeria, Lic. Enfermeria, Obstetra, Medico * I-2 : Lic. Enfermeria, Obstetra, Medico * I-3 : Lic. Enfermeria, Obstetra, Medico, Psicologo * I-4 : Lic. Enfermeria, Obstetra, Medico,ME,Psicologo | G17: * Edad minima: 00 dias * Edad Maxima: 120 años SEXO: * Ambos | H17: * Alta * Citado | I17: OBLIGATORIO: * 407 - Tamizaje de Salud Mental CONDICIONAL: * 005 - Edad Gestacional: EN CASO DE SER GESTANTE | J17: * Ap. Dx/Proc | K17: * Dia: 01 * Mes: 02 * Año: 04 * Intervalo: Ninguno AÑO CALENDARIO | L17: OBLIGATORIO: * Z133 - Examen de pesquisa especial para trastornos mentales y del comportamiento DE ACUERDO A LA EVALUACIÓN (OPCIONAL): * F99.X - Trastorno mental no especificado * F32.9 - Episodio depresivo no especificado * F41.9 - Transtorno de ansiedad no especificado * Z72.1 - Problemas relacionados al uso de alcohol * T748 - Otros síndromes del maltrato * R456 - Violencia Física * Z735 - PROBLEMAS RELACIONADOS CON EL CONFLICTO DEL ROL SOCIAL, NO CLASIFICADOS EN OTRA PARTE * Z734 - PROBLEMAS RELACIONADOS CON HABILIDADES SOCIALES INADECUADAS, NO CLASIFICADOS EN OTRA PARTE. | M17: OPCIONAL: * 99402.09 - CONSEJERÍA DE PREVENCIÓN DE RIESGOS EN SALUD MENTAL Ó * 99207 - Atención en salud mental
A18: MUJERES | B18: COD_010 | C18: =VLOOKUP(B18,SER!A:C,2,FALSE) -> Atención del puerperio normal | D18: =VLOOKUP(B18,SER!A:C,3,FALSE) -> Preventivo | E18: * Intramural * Extramural | F18: * I-1 : Tec. Enfermeria, Lic. Enfermeria, Obstetra, Medico. * I-2 : Tec. Enfermeria, Lic. Enfermeria, Obstetra, Medico. * I-3 : Obstetra, Medico. * I-4 : Obstetra, Medico,ME. | G18: * Edad minima: 09 años * Edad Maxima: 60 años SEXO: * Femenino | H18: * Alta - Cuando es el 2do y ultimo control * Citado - Primer control | I18: RC14: * 003 - Peso * 004 - Talla * 301 - P.A(mmHg) * 010 - Altura Uterina * 209 - Control de Puerperio | K18: * Dia: 01 * Mes: 02 * Año: 02 * Intervalo: Ninguno DESDE LA ULTIMA FECHA DE ATENCION DE PARTO O CESAREA | L18: OBLIGATORIO: * Z39.2 - SEGUIMIENTO POSTPARTO DE RUTINA OPCIONAL: * O990 - ANEMIA QUE COMPLICA EL EMBARAZO, EL PARTO Y EL PUERPERIO | M18: OPCIONAL: * 99211 - Consulta ambulatoria (PUERPERIO) * 85018 - Dosaje de Hemoglobina Ó * 85007 - Hemograma Ó * 85027 - Hemograma Completo Ó * 85031 - Hemograma completo, tercera generación | N18: MEDICAMENTO: * 03513 - Sulfato Ferroso + Acido Folico 400 mg + 60mg (30tab) 33577 Ó 35542 Ó 3552 INSUMOS: * 16571 - Guante para Examen Desacartable N° 7 1/2 (PAR) * 21377 - Lanceta Retractil Descartablle Adulto * 19698 - Microcubeta de Plastico Descartable para hemoglobinometro 10UI
A19: MUJERES | B19: COD_011 | C19: =VLOOKUP(B19,SER!A:C,2,FALSE) -> Exámenes de laboratorio completo de la gestante | D19: =VLOOKUP(B19,SER!A:C,3,FALSE) -> Preventivo | E19: * Intramural | F19: * I-2 : Tec. medico * I-3 : Tec. medico * I-4 : Tec. Medico. | G19: * Edad minima: 09 años * Edad Maxima: 60 años SEXO: * Femenino | H19: * Citado | I19: RC14: * 005 - Edad Gestacional OPCIONAL: * 003 - Peso * 004 - Talla * 015 - PAB * 301 - P.A(mmHg) | J19: * Ap. Dx/Proc | K19: * Dia: 01 * Mes: 01 * Año: 02 * Intervalo: Ninguno DESDE LA PRIMERA ATENCION DE GESTANTE | L19: OBLIAGTORIO: * Z017 - EXAMEN DE LABORATORIO | M19: OBLIGATORIO: RV19: * 80055 - Perfil Prenatal + 86899 - Grupo sanguíneo y Factor Rh * 82947 - Glucosa en sangre * 81005 - Exámen completo de orina * 86592 - Prueba de SIFILIS cualitativa (RPR, VDRL, ART) * 86701 - Prueba rápida/ELISA para VIH * 87340 - Hepatitis B
A20: VARONES | B20: COD_023 | C20: =VLOOKUP(B20,SER!A:C,2,FALSE) -> Deteccion precoz de cancer de prostata (PSA) | D20: =VLOOKUP(B20,SER!A:C,3,FALSE) -> Preventivo | E20: * Intramural | F20: * I-2 : BILG. * I-3 : Tec. medico * I-4 : Tec. Medico. | G20: * Edad minima: 50 años * Edad Maxima: 75 años SEXO: * Masculino | H20: * Alta * | I20: OPCIONAL: RC05: * 003 - Peso * 004 - Talla * 301 - P.A(mmHg) | J20: OBLIGATORIO: * Ap. Dx/Proc | K20: * Dia: 01 * Mes: 01 * Año: 01 * Intervalo: Ninguno AÑO CALENDARIO | L20: * Z018 - Otros examenes especiales Especificos Z125 EXAMEN DE PESQUISA ESPECIAL PARA TUMOR DE LA PROSTATA | M20: OPCIONAL: * 84152 -Dosaje de Antígeno prostático específico (PSA); complejos (medición directa). ó * 82270 - sangre oculta en heces Thevenom Resultados de laboratorio deben de ser (POSITIVO O NEGATIVO)
A21: MUJERES | B21: COD_024 | C21: =VLOOKUP(B21,SER!A:C,2,FALSE) -> Detección precoz de cáncer cérvico-uterino | D21: =VLOOKUP(B21,SER!A:C,3,FALSE) -> Preventivo | E21: * Intramural | F21: * I-1 : Obstetra. * I-2 : Obstetra, Medico. * I-3 : Obstetra, Medico. * I-4 : Obstetra, Medico, ME. | G21: * Edad minima: 25 años * Edad Maxima: 65 Años SEXO: * Femenino | H21: * Alta * | I21: RC14: * 005 - Edad Gestacional: EN CASO DE SER GESTANTE OPCIONAL: RC05: * 003 - Peso * 004 - Talla * 301 - P.A(mmHg) | J21: OBLIGATORIO: * Ap. Dx/Proc | K21: * Dia: 01 * Mes: 01 * Año: 01 * Intervalo: Ninguno AÑO CALENDARIO | L21: OBLIGATORIO: Z124 EXAMEN DE PESQUISA ESPECIAL PARA TUMOR DE CUELLO UTERINO | M21: OBLIGATORIO: * 88150.01 - CITO PATOLOGÍA CERVICAL 0 VAGINAL V TAMIZAJE MANUAL (PAPAN ICOLAOU) Ó * 88141.01 - INSPECCION VISUAL ACIDO ACETICO (IVAA) (30 a 49 años)(Debera colocar el RESULTADO de acuerdo al Hallazgo: NORMAL ó ANORMAL. * 99386.03 EXAMEN CLINICO DE MAMA | N21: * 22095 - ESPATULA - CITOCEPILLO CON ENVOLTURA INDIVIDUAL. * 16569 ó 16571 ó 16572 - Guante Quirurgico esteril *25791 - CAMPO QUIRURGICO DESCARTABLE 45 cm X 45 cm * 22710 - ESPECULO VAGINAL DESCARTABLE GRANDE * 25122- ESPECULO VAGINAL DESCARTABLE MEDIANO * 28687 - MANDIL DESCARTABLE ESTERIL TALLA M * 23127- MASCARILLA DESCARTABLE QUIRURGICA 3 PLIEGUES
A22: NEONATO | B22: COD_029 | C22: =VLOOKUP(B22,SER!A:C,2,FALSE) -> Tamizaje Neonatal | D22: =VLOOKUP(B22,SER!A:C,3,FALSE) -> Preventivo | E22: * Intramural | F22: * I-3: BILG, Tec Medc. * I-4 : Lic. Enfermeria, Medico, ME, BILG, Tec Medc.. | G22: * Edad minima: 00 dias * Edad Maxima: 12 meses SEXO: * Ambos | H22: * Alta * Citado | L22: * Z138 - EXAMEN DE PESQUISA ESPECIAL PARA OTRAS ENFERMEDADES Y TRASTORNOS ESPECIFICADOS | M22: OPCIONAL: * 36416 - COLECCIÓN DE SANGRE CAPILAR (ejemplo dedo,talon u oreja)
A23: NIÑO | B23: COD_050 | C23: =VLOOKUP(B23,SER!A:C,2,FALSE) -> Atención inmediata del recién nacido normal | D23: =VLOOKUP(B23,SER!A:C,3,FALSE) -> Recuperativo | E23: * Intramural | F23: * I-1 : Lic. Enfermeria, Obstetra, Medico * I-2 : Lic. Enfermeria, Obstetra, Medico * I-3 : Lic. Enfermeria, Medico. * I-4 : Lic. Enfermeria, Medico, ME | G23: * Edad minima: 00 dias * Edad Maxima: 02 dias SEXO: * Ambos | H23: * Alta * Citado | I23: RC14: * 304 - EDAD GESTACIONAL DEL RN (SEM) * 003 - Peso * 004 - Talla * 305 - APGAR 1º * 306 - APGAR 5º * 102 - BCG * 315 - HVB OPCIONAL: RC05: * 019 - Recien Nacido Prematuro * 020 - Bajo peso al nacer * 021 - Enfermedad Congénita/ Secuelas de nacimiento * 014 - IMC * 015 - PAB | J23: OBLIGATORIO: * Med/Ins * Ap. Dx/Proc | K23: * Dia: 01 * Mes: 01 * Año: 01 * Intervalo: Ninguno | L23: OPCIONAL: * Z370 - NACIDO VIVO, ÚNICO Ó * Z280 - INMUNIZACIÓN NO REALIZADA POR EL CONTRARIO INDICACIÓN (CUANDO NO SE REGISTRA LA INMUNIZACION DE LA HVB) | M23: OBLIGATORIO: * 99403.01 - Consejeria Nutricional Ó * 99401.02 - Consejeria en Lactacia materna * 86900 - Tipificación de sangre; ABO * 86901 - Tipificación de sangre; Rh (D) (POSITIVO y/o NEGATIVO) OPCIONAL: * 90782 - Inyectable intramuscular * 15854 - Curacion de Herida Primaria * 90471 - Inmunización | N23: MEDICAMENTO E INSUMOS OBLIGATORIO: 03576 - Fitomeniadiona, Obligatorio (Vit K) 06111 - TETRACICLINA CLORHIDRATO ungüento oftalmico 15287 - BRAZALETE DE IDENTIFICACION PARA NIÑO 15288- BRAZALETE DE IDENTIFICACION PARA NIÑA 15276 - BOMBILLA DE ASPIRACION N° 6 18931 - BOTA DESCARTABLE 11375 - JERINGA DESCARTABLE DE 1 ml CON AGUJA DE 25G X 3/8 10554 - CLAMP UMBILICAL 18726 - GORRO DESCARTABLE 16656 - JERINGA DESCARTABLE DE 1 mL con AGUJA DE 25 G X 5/8 21395 - MANDIL DESCARTABLE 11345 - AGUJA DESCARTABLE DE TUBERCULINA 1 ml CON AGUJA 25G X 3/8 OPCIONAL: * 01841 Ciprofloxacino ó * 18582 Sulfacetamida sódica ó
A24: MUJERES | B24: COD_054 | C24: =VLOOKUP(B24,SER!A:C,2,FALSE) -> Atención de parto vaginal | D24: =VLOOKUP(B24,SER!A:C,3,FALSE) -> Recuperativo | E24: * Intramural | F24: * I-1 : Tec. Enfermeria, Lic. Enfermeria, Obstetra, Medico * I-2 : Lic. Enfermeria, Obstetra, Medico * I-3 : Obstetra, Medico. * I-4 : Obstetra, Medico, ME. | G24: * Edad minima: 09 años * Edad Maxima: 60 años SEXO: * Femenino | H24: * Alta * Citado | I24: OBLIGATORIO: RC14: * 003 - Peso * 004 - Talla * 005 - Edad Gestacional * 301 - P.A(mmHg) OPCIONAL: RC05: * 408 - Parto Vertical * 409 - Corte Tardío de Cordón (2 a 3 min) * 014 - IMC * 015 - PAB * 010 - Altura uterina | J24: OBLIGATORIO: * Med/Ins * Ap. Dx/Proc | K24: * Dia: 01 * Mes: 01 * Año: 02 * Intervalo: 06 meses * DESDE LA ULTIMA FECHA DE ATENCION DE PARTO O CESAREA | L24: OPCIONALES: * O800 - Parto Único espontáneo, Presentación cefálica de vértice , ó * 0808 - Parto unico espontáneo, otras presentaciones. ó * O801 - Parto Unico espontáneo, Presentación de nalgas o podálica, ó * O364 - Atención materna por muerte intrauterina ó * P95X - Muerte fetal de causa no especificada. | M24: OBLIGATORIO: * 59400 - Atencion obstetrica de rutina incluyendo atención preparto, parto vaginal (con o sin episiotomía, y/o fórceps) y atención postparto /Control de puerperio * 99231 - Atención Paciente-Día Hospitalización * 90782 - Inyección profiláctica, diagnóstica o terapéutica; subcutánea o intramuscular OPCIONALES: * 99209 - Atencion en Nutrición * 96365 - Infusión I.V | N24: OBLIGATORIO: * 05253 - Oxitocina 10 UI. INSUMOS - OPCIONALES: * 25791 - Campo Qx desc. 45X 45 cm. * 18931 - Bota descartable para cirujano. * 18726 - Gorro descartable * 19492 - Mandilon descartable * 23127 - Mascarilla descartable Qx. * 19421 - Cateter Endovenoso N° 18. * 10929 - Equipo de venoclisis * 16571 - Guantes Qx 71/2. * 20361 - Llave de triple via * 38284 - Gasa esteri 10 x 10 x 16 plieges * 11370 - Jeringa descartable 5 ml * 11368 - Jeringa descartable 10 ml * 12018 - Sutura catgut cromico 2/0
A25: GENERAL | B25: COD_056 | C25: =VLOOKUP(B25,SER!A:C,2,FALSE) -> Consulta externa | D25: =VLOOKUP(B25,SER!A:C,3,FALSE) -> Recuperativo | E25: * Intramural | F25: * I-1 : Tec. Enfermeria, Lic. Enfermeria, Obstetra, Medico * I-2 : Lic. Enfermeria, Obstetra, Odontologo, Medico * I-3 : Nutricionista, Odontologo, Medico. * I-4 : Nutricionista, Odontologo, Medico, ME. | G25: * Edad minima: 00 dias * Edad Maxima: 120 años SEXO: * Ambos | H25: * Alta * Citado | I25: OBLIGATORIO: RC14: * 005 - Edad Gestacional : EN CASO DE SER GESTANTE * 301 - P.A(mmHg) * 003 - Peso * 004 - Talla | J25: OBLIGATORIO: * Med/Ins * Ap. Dx/Proc | L25: OPCIONALES: * Z018 - Otros examenes especiales especificados), * B159 - ( hepatitis A), * J00X - (rinofaringitis), * A09X - (diarrea acuosa), * u otros tipos de diagnosticos SEGÚN EVALUACION DEL PROFESIONAL QUE ATIENDE | N25: * Aplicación de medicamento o tratamiento según el diagnostico establecido.
A26: GENERAL | B26: COD_058 | C26: =VLOOKUP(B26,SER!A:C,2,FALSE) -> Obturación y curación dental compuesta | D26: =VLOOKUP(B26,SER!A:C,3,FALSE) -> Recuperativo | E26: * Intramural | F26: * I-2 : Odontologo. * I-3 : Odontologo. * I-4 : Odontologo. | G26: * Edad minima: 00 dias * Edad Maxima: 120 años SEXO: * Ambos | H26: * Alta * Citado | I26: RC14: * 005 - Edad Gestacional embarazo (en Semanas) | J26: OBLIGATORIO: * Ap. Dx/Proc | L26: OPCIONALES: * K020 - CARIES LIMITADA AL ESMALTE * K021 - CARIES DE LA DENTINA * K022- CARIES DEL CEMENTO * K029 - CARIES DENTAL, NO ESPECIFICADA Y/O OTRO DIAGNOSTICO DE ACUERDO CRITERIO DEL CIRUJANO DENTISTA. | M26: OPCIONAL: * D2391 - Tratamientos restauradores amalgama, silicato, otros materiales | N26: * 04394 - LIDOCAINA * 15045 - AGUJA CARPULE DENTAL DESCARTABLE N27 G x 1 5/8 * 16851 - GUANTES
A27: GENERAL | B27: COD_059 | C27: =VLOOKUP(B27,SER!A:C,2,FALSE) -> Extracción dental (exodoncia) | D27: =VLOOKUP(B27,SER!A:C,3,FALSE) -> Recuperativo | E27: * Intramural | F27: * I-2 : Odontologo. * I-3 : Odontologo. * I-4 : Odontologo. | G27: * Edad minima: 00 dias * Edad Maxima: 120 años SEXO: * Ambos | H27: * Alta * Citado | I27: RC14: * 005 - Edad Gestacional embarazo (en Semanas) | J27: OBLIGATORIO: * Med/Ins * Ap. Dx/Proc | L27: OPCIONALES: * K04.0 -PULPITIS, * K04.1 - NECROSIS PULPAR, * K07.3 ANOMALIAS DE LA POSICION DEL DIENTE Y/O OTRO DIAGNOSTICO DE ACUERDO CRITERIO DEL CIRUJANO DENTISTA. * K047 - Acceso periapical sin fistula | M27: D7176: Extracción Dental Simple | N27: INSUMOS: * 22963 - AGUJA CARPULE DENTAL DESCARTABLE Nª 27 G X 1 5/8" * 19029 - GUANTE QUIRURGICO DESCARTABLE ESTERIL Nº 7 (PAR) MEDICAMENTOS * 4394 - LIDOCAINA
A28: GENERAL | B28: COD_057 | C28: =VLOOKUP(B28,SER!A:C,2,FALSE) -> Obturación y curación dental simple | D28: =VLOOKUP(B28,SER!A:C,3,FALSE) -> Recuperativo | E28: * Intramural | F28: * I-2 : Odontologo. * I-3 : Odontologo. * I-4 : Odontologo. | G28: * Edad minima: 00 dias * Edad Maxima: 120 años SEXO: * Ambos | H28: * Alta * Citado | I28: RC14: * 005 - Edad Gestacional embarazo (en Semanas) | J28: OBLIGATORIO: * Med/Ins * Ap. Dx/Proc | L28: OPCIONALES: * K020 - CARIES LIMITADA AL ESMALTE * K021 - CARIES DE LA DENTINA * K022 - CARIES DEL CEMENTO * K029 - CARIES DENTAL, NO ESPECIFICADA | M28: OPCIONAL: * E2398 - D2390 : Restauración una superficie ionómero de vidrio en piezas dentales deciduas * E2398 - D2392 : Restauración una superficie ionómero de vidrio en piezas dentales permanentes * D2330 - 41720: Restauración fotocurable de una superficie con resina en piezas dentales posterior permanente * D2385 - Restauración de diente con resina, una superficie, posterior, permanente. * D2391 - Tratamientos restauradores amalgama, silicato, otros materiales
A29: GENERAL | B29: COD_060 | C29: =VLOOKUP(B29,SER!A:C,2,FALSE) -> Atención extramural urbana y perurbana (Visita domiciliaria) | D29: =VLOOKUP(B29,SER!A:C,3,FALSE) -> Recuperativo | E29: * Extramural | F29: * I-1 : Tec. Enfermeria,Lic. Enfermeria, Obstetra, Odontologo, Medico. * I-2 :Tec. Enfermeria,Lic. Enfermeria, Obstetra, Odontologo, Medico. * I-3 : Tec. Enfermeria,Lic. Enfermeria, Obstetra, Nutricionista, Odontologo, Medico, ME, Psicologo, BILG. * I-4 : Tec. Enfermeria,Lic. Enfermeria, Obstetra, Nutricionista, Odontologo, Medico, ME, Psicologo, BILG. | G29: * Edad minima: 00 dias * Edad Maxima: 120 años SEXO: * Ambos | I29: RC14: * 005 - Edad Gestacional: EN CASO DE SER GESTANTE | K29: * Dia: 01 * Mes: * Año: * Intervalo: | L29: 1er. Dx: * Z742 - Problemas relacionados con la necesidad de asistencia domiciliaria y que ningun otro miembro del hogar puede proporcionar. 2do Dx. Razon de la Visita: ejm. * D509 - ANEMIA * Z918 - RIESGO NUTRICIONAL y/ * Z724 - PROBLEMAS RELACIONADOS CON LA DIETA Y HABITOS ó ALIMENTICIOS. * Z001 - CONTROL DEL RECIEN NACIDO * O990 - ANEMIA QUE COMPLICA EL EMBARAZO, EL PARTO Y EL PUERPERIO OTROS DE ACUERDO A LA VISITA | M29: OPCIONAL: * 99344 - Consulta a domicilio para la evaluación y manejo de un paciente nuevo, de elevada severidad (VISITA FAMILIAR INTEGRAL) * 99342 - VISITA MÉDICA DOMICILIARIA (Solo por Médico) * 99349 - Consulta a domicilio para manejo y evaluacion de un paciente continuador de grave a moderado. * 99509 - Visita Domicilaria para la ayuda con actividades de la vida diaria y del cuidado personal. * (Niños con enfermedades prevalentes de la Infancia) * 90471 - Inmunización O ADMISNITRACION DE INMUNIZACIONES
A30: GENERAL | B30: COD_061 | C30: =VLOOKUP(B30,SER!A:C,2,FALSE) -> Atención en tópico | D30: =VLOOKUP(B30,SER!A:C,3,FALSE) -> Recuperativo | E30: * Intramural | F30: * I-1 : Tec. Enfermeria, Lic. Enfermeria, Obstetra,Odontologo, Medico, ME. * I-2 : Tec. Enfermeria, Lic. Enfermeria, Obstetra,Odontologo, Medico, ME. * I-3 :Lic. Enfermeria, Medico, ME. * I-4 : Lic. Enfermeria, Medico, ME.. | G30: * Edad minima: 00 dias * Edad Maxima: 120 años SEXO: * Ambos | H30: * Alta * Citado | I30: RC14: * 005 - Edad Gestacional: EN CASO DE SER GESTANTE | L30: LOS DIAGNOSTICOS REGISTRADOS SIEMPRE TIENEN QUE SER ; (REPETITIVOS) | M30: OPCIONAL: RC39: * 15878 - Curación de heridas pequeñas, menos de 5 cms * 97597 - Curación de heridas * 90471 Administración de Inmunización (incluye inyeccion percutánea, intradermica, subcutánea, intramuscular y/o adinistracion intranasal u oral, * 94640 - Tratamiento por inhalación con o sin presión para tratamiento de obstrucción aguda de las vías aéreas o para estimulación de esputo con fines diagnósticos * Retiro de puntos * Colocacion de sonda * Lavado de oidos | N30: Depende al Diagnostico
A31: GENERAL | B31: COD_062 | C31: =VLOOKUP(B31,SER!A:C,2,FALSE) -> Atención por emergencia | D31: =VLOOKUP(B31,SER!A:C,3,FALSE) -> Recuperativo | E31: * Intramural ATENCION * Emergencia | F31: * I-1 : Tec. Enfermeria, Lic. Enfermeria, Obstetra, Medico. * I-2 : Lic. Enfermeria, Obstetra, Medico. * I-3 :Lic. Enfermeria, Obstetra, Medico, ME. * I-4 : Medico, ME.. | G31: * Edad minima: 00 dias * Edad Maxima: 120 años SEXO: * Ambos | H31: * Alta * Citado | I31: RC14: * 005 - Edad Gestacional embarazo: EN CASO DE SER GESTANTE * 003 - Peso * 004 - Talla * 301 - P.A(mmHg) | J31: OBLIGATORIO: * Med/Ins * Ap. Dx/Proc | M31: OPCIONAL: * 94664 - Inhalaciones de aerosoles o vapores para movilización de esputo, broncodilatación o inducción del esputo con fines diagnósticos. * 99281- ATENCIÓN DE EMERGENCIA PRIORIDAD IV * 99282 - ATENCIÓN DE EMERGENCIA PRIORIDAD III * 99284 - ATENCIÓN DE EMERGENCIA PRIORIDAD II * 99285 - ATENCIÓN DE EMERGENCIA PRIORIDAD I + * OTROS PROCEDIMIENTOS QUE SE REALIZA + * OTROS PROCEDIMIENTOS QUE SE REALIZA DE ACUERDO A LA RJ N° 017-2019/SIS, RJ N° 99-2019/SIS.
A32: GENERAL | B32: COD_063 | C32: =VLOOKUP(B32,SER!A:C,2,FALSE) -> Atención por emergencia con observación | D32: =VLOOKUP(B32,SER!A:C,3,FALSE) -> Recuperativo | E32: * Intramural | F32: * I-2 : Lic, Enfermeria, Obstetra, Medico, ME. * I-3 : Medico, ME. * I-4 : Medico, ME.. | G32: * Edad minima: 00 dias * Edad Maxima: 120 años SEXO: * Ambos | H32: * Alta * Citado | I32: RC14: * 005 - Edad Gestacional embarazo (en Semanas) * 003 - Peso * 004 - Talla * 301 - P.A(mmHg) RC05: * 014 - IMC * 015 - PAB | J32: OBLIGATORIO: * Med/Ins * Ap. Dx/Proc | M32: OPCIONAL: * 57520 - Conización del cervix, con o sin fulguración, con o sin dilatación y legrado, con o sin corrección;cuchillo frío o láser * 57522 - Conización del cervix, con o sin fulguración, con o sin dilatación y legrado, con o sin corrección; escisión con electrodo de asa * 99282 - Atención de Emergencia, Prioridad I * 99283 - Atención de Emergencia, Prioridad II * 99284 - Atención de Emergencia, Prioridad III * 99285 - Atención de Emergencia, Prioridad IV * 99234 - Atención en sala de observación * OTROS PROCEDIMIENTOS QUE SE REALIZA * OTROS PROCEDIMIENTOS QUE SE REALIZA DE ACUERDO A LA RJ N° 017-2019/SIS, RJ N° 99-2019/SIS.
A33: GENERAL | B33: COD_065 | C33: =VLOOKUP(B33,SER!A:C,2,FALSE) -> Internamiento en EESS sin intervención quirúrgica | D33: =VLOOKUP(B33,SER!A:C,3,FALSE) -> Recuperativo | E33: * Intramural | F33: * I-4 : ME. | G33: * Edad minima: 29 dias * Edad Maxima: 120 años SEXO: * Ambos | H33: * Alta * Citado | I33: RC14: * 005 - Edad Gestacional embarazo (en Semanas) RC05: * 003 - Peso * 004 - Talla * 301 - P.A(mmHg) | J33: OBLIGATORIO: * Med/Ins * Ap. Dx/Proc | L33: * O234 - INFECCION NO ESPECIFICADA DE LAS VIAS URINARIAS EN EL EMBARAZO * SEGÚN CORRESPONDA | M33: * 99211 - Consulta ambulatoria para la evaluación y manejo de una paciente continuador, nivel I * 99231 - Atención Paciente-Día Hospitalización * 90784 - Inyección terapéutica o diagnóstica intravenosa * 90782 - Inyección profiláctica, diagnóstica o terapéutica; subcutánea o intramuscular * 99305 - Atención Paciente-Día Cuidados Intermedios * 99282 - Atención de Emergencia, Prioridad I * 99283 - Atención de Emergencia, Prioridad II * 99284 - Atención de Emergencia, Prioridad III * 99285 - Atención de Emergencia, Prioridad IV
A34: GENERAL | B34: COD_071 | C34: =VLOOKUP(B34,SER!A:C,2,FALSE) -> Apoyo al diagnóstico | D34: =VLOOKUP(B34,SER!A:C,3,FALSE) -> Recuperativo | E34: * Intramural | F34: * I-2 : Tecnico en Laboratorio. * I-3 : Medico, Tecnico en Laboratorio Tec. Med. * I-4 : Medico, ME, BILG, Tec. Med.. | G34: * Edad minima: 00 dias * Edad Maxima: 120 años SEXO: * Ambos | H34: * Citado | I34: RC14: * 005 - Edad Gestacional embarazo: EN CASO DE SER GESTANTE | J34: OBLIGATORIO: * Ap. Dx/Proc | L34: OPCIONALES: * Z017 - Examen de Laboratorio. | M34: OPCIONAL: * 81005 - Exámen completo de orina * 85018 - Dosaje de Hemoglobina Ó * 85007 - Hemograma Ó * 85027 - Hemograma Completo Ó * 85031 - Hemograma completo, tercera generación * 86701 - HIV-1, anticuerpos * DE ACUERDO A SOLICITUD DE EXAMENES DE APOYO AL DIAGNOSTICO EMITIDA POR PROFESIONAL
A35: GENERAL | B35: COD_074 | C35: =VLOOKUP(B35,SER!A:C,2,FALSE) -> Tratamiento de ITS en adolescentes, adultos y adultos mayores | D35: =VLOOKUP(B35,SER!A:C,3,FALSE) -> Recuperativo | E35: * Intramural | F35: * I-1 : Lic. Enfermeria, Obstetra. * I-2 : Lic. Enfermeria, Obstetra, Medico. * I-3 : Obstetra, Medico. * I-4 : Obstetra, Medico, ME. | G35: * Edad minima: 10 años * Edad Maxima: 120 años SEXO: * Ambos | H35: * Alta * Citado | I35: CONDICIONAL: * 005 - Edad Gestacional embarazo: EN CASO DE SER GESTANTE OPCIONAL: * 003 - Peso * 004 - Talla * 301 - P.A(mmHg) | J35: OBLIGATORIO: * Med/Ins | L35: OPCIONAL: * N760 - Vaginitis Aguda * A64X - Enfermedad De Transmisión Sexual No Especificada * N739 - Enfermedad Inflamatoria Sexual No Especificada * R36X - Desacarga Uretral * A539 - Sifiis, No especificada | M35: OPCIONAL: * 99402.05 - CONSEJERÍA/ORIENTACIÓN EN PREVENCIÓN DE ITS, VIH, HEPATITIS B
A36: GENERAL | B36: COD_075 | C36: =VLOOKUP(B36,SER!A:C,2,FALSE) -> Atención extramural rural (Visita domiciliaria) | D36: =VLOOKUP(B36,SER!A:C,3,FALSE) -> Recuperativo | E36: * Extramural | F36: * I-1 : Tec. Enfermeria,Lic. Enfermeria, Obstetra, Odontologo, Medico. * I-2 :Tec. Enfermeria,Lic. Enfermeria, Obstetra, Odontologo, Medico. * I-3 : Tec. Enfermeria,Lic. Enfermeria, Obstetra, Nutricionista, Odontologo, Medico, ME, Psicologo, BILG. * I-4 : Tec. Enfermeria,Lic. Enfermeria, Obstetra, Nutricionista, Odontologo, Medico, ME, Psicologo, BILG. | G36: * Edad minima: 00 dias * Edad Maxima: 120 años SEXO: * Ambos | I36: RC14: * 005 - Edad Gestacional embarazo: EN CASO DE SER GESTANTE | K36: * Dia: 01 * Mes: 00 * Año: 00 * Intervalo: Ninguno | L36: 1er. Dx: * Z742 - Problemas relacionados con la necesidad de asistencia domiciliaria y que ningun otro miembro del hogar puede proporcionar. ó | M36: OPCIONAL: * 99344 - Consulta a domicilio para la evaluación y manejo de un paciente nuevo, de elevada severidad (VISITA FAMILIAR INTEGRAL) * 99342 - VISITA MÉDICA DOMICILIARIA (Solo por Médico) Razon de la Visita, Describir en OBSERVACION: ejm. ANEMIA PROBLEMAS RELACIONADOS CON LA DIETA Y HABITOS ó ALIMENTICIOS. CONTROL DEL RECIEN NACIDO ANEMIA QUE COMPLICA EL EMBARAZO, EL PARTO Y EL PUERPERIO OTROS DE ACUERDO A LA VISITA
A37: NIÑO | B37: COD_118 | C37: =VLOOKUP(B37,SER!A:C,2,FALSE) -> Control de crecimiento y desarrollo en menores de 5 - 9 años | D37: =VLOOKUP(B37,SER!A:C,3,FALSE) -> Preventivo | E37: * Intramural | F37: * I-1 : Tec. Enfermeria,Lic. Enfermeria, Obstetra, Medico. * I-2 :Tec. Enfermeria,Lic. Enfermeria, Obstetra, Medico. * I-3 :Lic. Enfermeria, Medico. * I-4 : Lic. Enfermeria, Medico, ME. | G37: * Edad minima: 05 Años * Edad Maxima: 09 Años SEXO: * Ambos | H37: * Alta SIEMPRE TIENE QUE SER ALTA POR QUE LE CORRESPONDE UN SOLO CRED | I37: RC14: * 003 - Peso * 004 - Talla * 019 - Prematuro al Nacer * 020 - Bajo peso al nacer * 021 - Enfermedades Congénita/Secuelas de Nacimiento * 120 - Control CRED | K37: * Dia: 01 * Mes : 01 * Año: 01 NACIMIENTO | L37: OBLIGATORIO: * Z001 - Control de Salud de rutina del niño (Niño Normal) (Z001) OPCIONAL: * E43X - Desnutrición Proteico calórica Severa, No Especificada (Delgadez severa) Ó * Z91.8 - Historia personal de otros factores de riesgo, no clasificados en otra parte (Riesgo de desnutrición). Ó * E440 - Desnutrición Proteico calórica Moderada (Delgadez) ) Ó * E660 - Obesidad debida a exceso de Calorías (Sobrepeso) Ó * E669 - Obesidad, No especificada ADICIONAL: * E45X - Retardo del Desarrollo debido a Desnutrición Proteico calórica (Talla baja) Ó * E344 - Estatura alta Constitucional (Talla alta) | M37: OPCIONAL: *99383 - ATENCIÓN INTEGRAL DE SALUD DEL NIÑO CRED DE 05 A 09 AÑOS. * 90471 - Inmunización * 85018 - DOSAJE DE HEMOGLOBINA (VALOR AJUSTADO). Si los valores estan por debajo de los rangos establecidos debera registrar diagnostico de Anemia. | N37: INSUMOS: * 30586 - LANCETA RETRACTIL 1 UNIDAD * 33891 - MICROCUBETA HEMOCUE.-1 UNIDAD * 33481 - MICROCUBETA HEMOCONTRO-1 UND * 23367- GUANTE PARA EXAMEN TALLA M - 1 UNIDAD ó * 23726 - GUANTE PARA EXAMEN TALLA S - 1 UNIDAD
A38: NIÑO | B38: COD_119 | C38: =VLOOKUP(B38,SER!A:C,2,FALSE) -> Control de crecimiento y desarrollo en menores de 10 - 12 años | D38: =VLOOKUP(B38,SER!A:C,3,FALSE) -> Preventivo | E38: * Intramural | F38: * I-1 : Tec. Enfermeria,Lic. Enfermeria, Obstetra, Medico. * I-2 :Tec. Enfermeria,Lic. Enfermeria, Obstetra, Medico. * I-3 :Lic. Enfermeria, Nutricionista, Medico. * I-4 : Lic. Enfermeria, Nutricionista, Medico, ME. | G38: * Edad minima: 10 Años * Edad Maxima: 11 Años SEXO: * Ambos | H38: * Alta SIEMPRE ES ALTA YA QUE SOLO LE CORRESPONDE UN SOLO CRED | I38: OPCIONAL: RC14: * 003 - Peso * 004 - Talla * 019 - Prematuro al Nacer * 020 - Bajo peso al nacer * 021 - Enfermedades Congénita/Secuelas de Nacimiento * 120 - Control CRED | L38: OBLIGATORIO: * Z743 - Problemas relacionados con la necesidad de supervision continua. | M38: RC31: * 85018 - Dosaje de Hemoglobina Ó * 85007 - Hemograma Ó * 85027 - Hemograma Completo Ó * 85031 - Hemograma completo, tercera generación RC39: * 92015 - Refracción y medición de la visión
A39: MUJERES | B39: COD_902 | C39: =VLOOKUP(B39,SER!A:C,2,FALSE) -> Atención Preconcepcional | D39: =VLOOKUP(B39,SER!A:C,3,FALSE) -> Preventivo | E39: * Intramural | F39: * I-1 : Obstetra, MEDICO * I-2 : Obstetra, Medico. | G39: * Edad minima: 18 años * Edad Maxima: 45 años SEXO: * Femenino | H39: * Alta * Citado | I39: OBLIGATORIO: RC14 * 003 - Peso * 004 - Talla * 014 - IMC * 015 - PAB * 301 - P.A(mmHg) | J39: OBLIGATORIO: * Med/Ins * Ap. Dx/Proc | K39: * Dia: 01 * Mes: 01 * Año: 03 * Intervalo: Ninguno AÑO CALENDARIO | L39: OPCIONALES: * Z316 - Consejo y Asesoramiento General Sobre La Procreación Ó * Z008 - Otros Examenes Especiales | M39: OPCIONAL: RC46: * 99401.01 - Consejería en Inmunizaciones * 99403 - Consejería nutricional * 85018 - Dosaje de hemoglobina * 86701 - Detección de anticuerpos para HIV-1 / HIV -2 * 86703 - ELISA o prueba rápida para HIV-1 y HIV-2 -Test de ELISA para HIV * 86592 - Prueba de sífilis cualitativa (VDRL, RPR) -Prueba de sífilis cualitativa (VDRL, RPR, ART) * 82948 - Glucosa (tira reactiva) * 81000 - Examen de orina con tira reactiva | N39: MEDICAMENTO: * 00200 - ACIDO FOLICO (30Tab en las 3 atenciones)
A40: ADULTO MAYOR | B40: COD_903 | C40: =VLOOKUP(B40,SER!A:C,2,FALSE) -> Atención Integral de Salud del Adulto Mayor | D40: =VLOOKUP(B40,SER!A:C,3,FALSE) -> Preventivo | E40: * Intramural | F40: * I-1 : Tec. Enfermeria,Lic. Enfermeria, Obstetra, Medico. * I-2 : Lic. Enfermeria, Obstetra, Medico. * I-3 :Lic. Enfermeria, Obstetra, Medico, ME. * I-4 : Lic. Enfermeria, Obstetra, Medico, ME. | G40: * Edad minima: 60 años * Edad Maxima: 120 años SEXO: * Ambos | H40: * Alta * Citado | I40: RC14: * 003 - Peso * 004 - Talla * 014 - IMC * 015 - PAB * 301 - P.A(mmHg) RC05: * 018 - Valoración Clínica del Adulto Mayor (VACAM) anual | J40: OBLIGATORIO: * Med/Ins * Ap. Dx/Proc | K40: * Dia: 01 * Mes: 02 * Año: 04 * Intervalo: Ninguno EDAD CUMPLIDA | L40: OBLIGATORIO: * Z000 - EXAMEN MEDICO GENERAL(NORMAL) Z008 OTROS EXAMENES GENERALES (NORMAL) OPCIONAL: * E440 - Desnutrición Proteico calórica Moderada (Delgadez) ó * E660 - Obesidad debida a exceso de Calorías (Sobrepeso) ó * E669 - Obesidad, No especificada . | M40: OPCIONAL: * 85018 - Dosaje de Hemoglobina 82947 - Glucosa Basal (Colocar Resultado Númerico) 82948 - Glucosa (tira reactiva) (Colocar Resultado Númerico) 80061 - Perfil Lidíco ( Colocar Resultado (Normal ó Patologico) 82465 - Colesterol Total (Colocar Resultado (Normal ó Patologico 84478 - Trigliceridos ( Colocar Resultado Valor) OJO TAMBIEN PUEDE IR ANEXADO CON LA PRESTACON 071 EXAMENES DE LABORATORIO
...

Sheet Hoja1
A1: COD_PRESTA
A2: COD_001
A3: COD_002
A4: COD_005
A5: COD_007
A6: COD_008
A7: COD_009
A8: COD_010
A9: COD_011
A10: COD_013
A11: COD_015
A12: COD_016
... A30: COD_118

Sheet SER
A1: COD_001 | B1: Control de crecimiento y desarrollo en menores de 0 - 4 años | C1: Preventivo
A2: COD_002 | B2: Control del recién nacido con menos de 2,500 gr, prematuro, con secuelas al nacer | C2: Preventivo
A3: COD_003 | B3: Ex. inmunologico del niño nacido de madre VIH+ (*) | C3: Preventivo
A4: COD_004 | B4: Ex. Inmunologico de niño nacido de madre RPR o VDRL+ | C4: Preventivo
A5: COD_005 | B5: Consejería nutricional para niñas o niños en riesgo nutricional y desnutrición | C5: Preventivo
A6: COD_007 | B6: Suplemento de micronutrientes | C6: Preventivo
A7: COD_008 | B7: Profilaxis antiparasitaria | C7: Preventivo
A8: COD_009 | B8: Atención prenatal | C8: Preventivo
A9: COD_010 | B9: Atención del puerperio normal | C9: Preventivo
A10: COD_011 | B10: Exámenes de laboratorio completo de la gestante | C10: Preventivo
A11: COD_013 | B11: Exámenes de ecografía obstétrica | C11: Preventivo
A12: COD_014 | B12: Tamizaje de HIV a gestante | C12: Preventivo
... A179: COD_911 | B179: Instrucción de Higiene Oral y Asesoría nutricional para el control de enfermedades dentales | C179: Recuperativo
